{
  "comments": [
    {
      "unresolved": false,
      "key": {
        "uuid": "5f6c5116_f70a1787",
        "filename": "/PATCHSET_LEVEL",
        "patchSetId": 9
      },
      "lineNbr": 0,
      "author": {
        "id": 34543
      },
      "writtenOn": "2024-02-28T23:34:48Z",
      "side": 1,
      "message": "LGTM, thanks",
      "revId": "b7e11191ca92a9b4370aee27662fad6bf5f9cb45",
      "serverId": "4a232e18-c5a9-48ee-94c0-e04e7cca6543"
    },
    {
      "unresolved": true,
      "key": {
        "uuid": "ee03c2fc_b59b9559",
        "filename": "charms/tempest-k8s/src/charm.py",
        "patchSetId": 9
      },
      "lineNbr": 302,
      "author": {
        "id": 10366
      },
      "writtenOn": "2024-02-29T01:19:56Z",
      "side": 1,
      "message": "This case should not arise as check_relation_handlers_ready() is run as part of super().configure_unit(event) and the relation is mentioned as mandatory_relation.\n\nIf you are still getting user_id_ops not ready, this should be a bug that needs to be fixed in ops_sunbeam. Can you let us know the scenario when this is happening.",
      "revId": "b7e11191ca92a9b4370aee27662fad6bf5f9cb45",
      "serverId": "4a232e18-c5a9-48ee-94c0-e04e7cca6543"
    },
    {
      "unresolved": true,
      "key": {
        "uuid": "75c76d46_9a4900d1",
        "filename": "charms/tempest-k8s/src/charm.py",
        "patchSetId": 9
      },
      "lineNbr": 302,
      "author": {
        "id": 10366
      },
      "writtenOn": "2024-02-29T01:23:13Z",
      "side": 1,
      "message": "Can you check if this is hit during the scenario https://opendev.org/openstack/sunbeam-charms/src/branch/main/ops-sunbeam/ops_sunbeam/charm.py#L373",
      "parentUuid": "ee03c2fc_b59b9559",
      "revId": "b7e11191ca92a9b4370aee27662fad6bf5f9cb45",
      "serverId": "4a232e18-c5a9-48ee-94c0-e04e7cca6543"
    },
    {
      "unresolved": true,
      "key": {
        "uuid": "44c3a454_4bbd08cc",
        "filename": "charms/tempest-k8s/src/charm.py",
        "patchSetId": 9
      },
      "lineNbr": 302,
      "author": {
        "id": 34352
      },
      "writtenOn": "2024-02-29T01:34:08Z",
      "side": 1,
      "message": "Ok that makes sense, thanks.  I\u0027ll remove it.",
      "parentUuid": "75c76d46_9a4900d1",
      "revId": "b7e11191ca92a9b4370aee27662fad6bf5f9cb45",
      "serverId": "4a232e18-c5a9-48ee-94c0-e04e7cca6543"
    },
    {
      "unresolved": false,
      "key": {
        "uuid": "254d817f_6c0c84a4",
        "filename": "charms/tempest-k8s/src/charm.py",
        "patchSetId": 9
      },
      "lineNbr": 302,
      "author": {
        "id": 34352
      },
      "writtenOn": "2024-02-29T02:03:32Z",
      "side": 1,
      "message": "Btw I don\u0027t think I observed this actually happening, it was more of a \"just to make sure\" case because I was having troubles tracing if configure_unit would actually be skipped if the relation wasn\u0027t ready.  Probably what I observed at one point - running before ready - was when the ready method wasn\u0027t checking all the required fields set.\n\nDone",
      "parentUuid": "44c3a454_4bbd08cc",
      "revId": "b7e11191ca92a9b4370aee27662fad6bf5f9cb45",
      "serverId": "4a232e18-c5a9-48ee-94c0-e04e7cca6543"
    }
  ]
}